2025-05-23 15:30:22,678 [INFO] Logging initialized. Log file: logs/linkedin_scraper_20250523_153022.log
2025-05-23 15:30:22,678 [INFO] Using Google credentials from gen-lang-client-0669898182-f88dce7f97c7.json
2025-05-23 15:30:22,680 [INFO] Starting automatic continuous monitoring...
2025-05-23 15:30:22,680 [INFO] Started new monitoring thread
2025-05-23 15:30:22,680 [INFO] Using Sheet ID: 1srvBC83XVx1LS4d8gIiwkWM41sS0Yu3puOHmzwlixrY
2025-05-23 15:30:22,680 [INFO] LinkedIn credentials configured: Yes
2025-05-23 15:30:22,680 [INFO] Initializing Google Sheets service using service account file: gen-lang-client-0669898182-80f330433de5.json
2025-05-23 15:30:22,796 [INFO] Successfully loaded credentials from service account file
2025-05-23 15:30:22,797 [INFO] file_cache is only supported with oauth2client<4.0.0
2025-05-23 15:30:22,800 [INFO] Successfully built Google Sheets service
2025-05-23 15:30:22,929 [INFO] Successfully verified spreadsheets() method availability
2025-05-23 15:30:22,929 [INFO] Successfully connected to Google Sheets service
2025-05-23 15:30:22,929 [INFO] Checking for blank rows in Google Sheet...
2025-05-23 15:30:23,250 [ERROR] Error in continuous monitoring: ('invalid_grant: Invalid JWT Signature.', {'error': 'invalid_grant', 'error_description': 'Invalid JWT Signature.'})
2025-05-23 15:30:23,250 [ERROR] Stack trace:
Traceback (most recent call last):
  File "/Users/varunisrani/pppp-4/app.py", line 87, in start_continuous_monitoring
    blank_rows = find_blank_rows(sheet_id, service, logger)
                 ^^^^^^^^^^^^^^^^^^^^^^^^^^^^^^^^^^^^^^^^^^
  File "/Users/varunisrani/pppp-4/continuous_linkedin_scraper.py", line 140, in find_blank_rows
    sheet = service.spreadsheets().get(spreadsheetId=sheet_id).execute()
            ^^^^^^^^^^^^^^^^^^^^^^^^^^^^^^^^^^^^^^^^^^^^^^^^^^^^^^^^^^^^
  File "/Users/varunisrani/.pyenv/versions/3.11.11/lib/python3.11/site-packages/googleapiclient/_helpers.py", line 130, in positional_wrapper
    return wrapped(*args, **kwargs)
           ^^^^^^^^^^^^^^^^^^^^^^^^
  File "/Users/varunisrani/.pyenv/versions/3.11.11/lib/python3.11/site-packages/googleapiclient/http.py", line 923, in execute
    resp, content = _retry_request(
                    ^^^^^^^^^^^^^^^
  File "/Users/varunisrani/.pyenv/versions/3.11.11/lib/python3.11/site-packages/googleapiclient/http.py", line 191, in _retry_request
    resp, content = http.request(uri, method, *args, **kwargs)
                    ^^^^^^^^^^^^^^^^^^^^^^^^^^^^^^^^^^^^^^^^^^
  File "/Users/varunisrani/.pyenv/versions/3.11.11/lib/python3.11/site-packages/google_auth_httplib2.py", line 209, in request
    self.credentials.before_request(self._request, method, uri, request_headers)
  File "/Users/varunisrani/.pyenv/versions/3.11.11/lib/python3.11/site-packages/google/auth/credentials.py", line 239, in before_request
    self._blocking_refresh(request)
  File "/Users/varunisrani/.pyenv/versions/3.11.11/lib/python3.11/site-packages/google/auth/credentials.py", line 202, in _blocking_refresh
    self.refresh(request)
  File "/Users/varunisrani/.pyenv/versions/3.11.11/lib/python3.11/site-packages/google/oauth2/service_account.py", line 448, in refresh
    access_token, expiry, _ = _client.jwt_grant(
                              ^^^^^^^^^^^^^^^^^^
  File "/Users/varunisrani/.pyenv/versions/3.11.11/lib/python3.11/site-packages/google/oauth2/_client.py", line 299, in jwt_grant
    response_data = _token_endpoint_request(
                    ^^^^^^^^^^^^^^^^^^^^^^^^
  File "/Users/varunisrani/.pyenv/versions/3.11.11/lib/python3.11/site-packages/google/oauth2/_client.py", line 270, in _token_endpoint_request
    _handle_error_response(response_data, retryable_error)
  File "/Users/varunisrani/.pyenv/versions/3.11.11/lib/python3.11/site-packages/google/oauth2/_client.py", line 69, in _handle_error_response
    raise exceptions.RefreshError(
google.auth.exceptions.RefreshError: ('invalid_grant: Invalid JWT Signature.', {'error': 'invalid_grant', 'error_description': 'Invalid JWT Signature.'})
2025-05-23 15:30:23,259 [INFO] Waiting 30 seconds before retrying...
2025-05-23 15:30:27,800 [INFO] [31m[1mWARNING: This is a development server. Do not use it in a production deployment. Use a production WSGI server instead.[0m
 * Running on all addresses (0.0.0.0)
 * Running on http://127.0.0.1:10000
 * Running on http://192.168.91.183:10000
2025-05-23 15:30:27,800 [INFO] [33mPress CTRL+C to quit[0m
2025-05-23 15:30:53,266 [INFO] Initializing Google Sheets service using service account file: gen-lang-client-0669898182-80f330433de5.json
2025-05-23 15:30:53,381 [INFO] Successfully loaded credentials from service account file
2025-05-23 15:30:53,384 [INFO] file_cache is only supported with oauth2client<4.0.0
2025-05-23 15:30:53,390 [INFO] Successfully built Google Sheets service
2025-05-23 15:30:53,526 [INFO] Successfully verified spreadsheets() method availability
2025-05-23 15:30:53,526 [INFO] Successfully connected to Google Sheets service
2025-05-23 15:30:53,526 [INFO] Checking for blank rows in Google Sheet...
2025-05-23 15:30:53,924 [ERROR] Error in continuous monitoring: ('invalid_grant: Invalid JWT Signature.', {'error': 'invalid_grant', 'error_description': 'Invalid JWT Signature.'})
2025-05-23 15:30:53,926 [ERROR] Stack trace:
Traceback (most recent call last):
  File "/Users/varunisrani/pppp-4/app.py", line 87, in start_continuous_monitoring
    blank_rows = find_blank_rows(sheet_id, service, logger)
                 ^^^^^^^^^^^^^^^^^^^^^^^^^^^^^^^^^^^^^^^^^^
  File "/Users/varunisrani/pppp-4/continuous_linkedin_scraper.py", line 140, in find_blank_rows
    sheet = service.spreadsheets().get(spreadsheetId=sheet_id).execute()
            ^^^^^^^^^^^^^^^^^^^^^^^^^^^^^^^^^^^^^^^^^^^^^^^^^^^^^^^^^^^^
  File "/Users/varunisrani/.pyenv/versions/3.11.11/lib/python3.11/site-packages/googleapiclient/_helpers.py", line 130, in positional_wrapper
    return wrapped(*args, **kwargs)
           ^^^^^^^^^^^^^^^^^^^^^^^^
  File "/Users/varunisrani/.pyenv/versions/3.11.11/lib/python3.11/site-packages/googleapiclient/http.py", line 923, in execute
    resp, content = _retry_request(
                    ^^^^^^^^^^^^^^^
  File "/Users/varunisrani/.pyenv/versions/3.11.11/lib/python3.11/site-packages/googleapiclient/http.py", line 191, in _retry_request
    resp, content = http.request(uri, method, *args, **kwargs)
                    ^^^^^^^^^^^^^^^^^^^^^^^^^^^^^^^^^^^^^^^^^^
  File "/Users/varunisrani/.pyenv/versions/3.11.11/lib/python3.11/site-packages/google_auth_httplib2.py", line 209, in request
    self.credentials.before_request(self._request, method, uri, request_headers)
  File "/Users/varunisrani/.pyenv/versions/3.11.11/lib/python3.11/site-packages/google/auth/credentials.py", line 239, in before_request
    self._blocking_refresh(request)
  File "/Users/varunisrani/.pyenv/versions/3.11.11/lib/python3.11/site-packages/google/auth/credentials.py", line 202, in _blocking_refresh
    self.refresh(request)
  File "/Users/varunisrani/.pyenv/versions/3.11.11/lib/python3.11/site-packages/google/oauth2/service_account.py", line 448, in refresh
    access_token, expiry, _ = _client.jwt_grant(
                              ^^^^^^^^^^^^^^^^^^
  File "/Users/varunisrani/.pyenv/versions/3.11.11/lib/python3.11/site-packages/google/oauth2/_client.py", line 299, in jwt_grant
    response_data = _token_endpoint_request(
                    ^^^^^^^^^^^^^^^^^^^^^^^^
  File "/Users/varunisrani/.pyenv/versions/3.11.11/lib/python3.11/site-packages/google/oauth2/_client.py", line 270, in _token_endpoint_request
    _handle_error_response(response_data, retryable_error)
  File "/Users/varunisrani/.pyenv/versions/3.11.11/lib/python3.11/site-packages/google/oauth2/_client.py", line 69, in _handle_error_response
    raise exceptions.RefreshError(
google.auth.exceptions.RefreshError: ('invalid_grant: Invalid JWT Signature.', {'error': 'invalid_grant', 'error_description': 'Invalid JWT Signature.'})
2025-05-23 15:30:53,930 [INFO] Waiting 30 seconds before retrying...
